<?xml version="1.0"?>
<robot name="RT1003">

  <link name="vehicle_link"></link>

  <link name="oxts_link">
    <visual>
      <origin rpy="0 0 -1.57079632679" xyz="-0.102 0.053 -0.015"/>
      <geometry>
        <mesh filename="package://oxts_driver/urdf/medium.stl" scale="0.001 0.001 0.001"/>
      </geometry>
      <material name="oxts_red">
        <color rgba="0.792 0.094 0.11 1.0"/>
      </material>
    </visual>
  </link>
  <joint name="vehicle_link_joint" type="floating">
    <parent link="vehicle_link"/>
    <child link="oxts_link" />
    <origin xyz="0 0 0" rpy="0 0 0" />
  </joint>

  <link name="imu_link"> </link>
  <joint name="imu_joint" type="fixed">
    <parent link="oxts_link" />
    <child link="imu_link" />
    <origin xyz="0 0 0" rpy="0 0 0" />
  </joint>

  <link name="navsat_link"> </link>
  <joint name="navsat_joint" type="fixed">
    <parent link="oxts_link" />
    <child link="navsat_link" />
    <origin xyz="0 0 0" rpy="0 0 0" />
  </joint>
</robot>
