<?xml version="1.0"?>
<robot name="RT1003">

  <link name="oxts_link">
    <visual>
      <origin rpy="0 0 0" xyz="-0.102 -0.024067 -0.015"/>
      <geometry>
        <mesh filename="package://oxts_ins/urdf/small_core.stl" scale="0.001 0.001 0.001"/>
      </geometry>
      <material name="oxts_red">
        <color rgba="0.792 0.094 0.11 1.0"/>
      </material>
    </visual>
  </link>

  <link name="rear_axle_link">
    <visual>
      <origin rpy="1.57075 0 0"/>
      <geometry>
        <cylinder length="1.6" radius="0.2"/>
      </geometry>
    </visual>
  </link>
  <joint name="rear_axle_joint" type="floating">
    <parent link="oxts_link"/>
    <child link="rear_axle_link" />
    <origin xyz="0 0 0" rpy="0 0 0" />
  </joint>

  <link name="front_axle_link">
    <visual>
      <origin rpy="1.57075 0 0"/>
      <geometry>
        <cylinder length="1.6" radius="0.2"/>
      </geometry>
    </visual>
  </link>
  <joint name="front_axle_joint" type="floating">
    <parent link="oxts_link"/>
    <child link="front_axle_link" />
    <origin xyz="0 0 0" rpy="0 0 0" />
  </joint>

  <link name="imu_link"> </link>
  <joint name="imu_joint" type="fixed">
    <parent link="oxts_link" />
    <child link="imu_link" />
    <origin xyz="0 0 0" rpy="0 0 0" />
  </joint>

  <link name="navsat_link"> </link>
  <joint name="navsat_joint" type="fixed">
    <parent link="oxts_link" />
    <child link="navsat_link" />
    <origin xyz="0 0 0" rpy="0 0 0" />
  </joint>
</robot>
